{"name": "test_xfail_expected_failure", "status": "skipped", "statusDetails": {"message": "AssertionError: assert False", "trace": "self = <test_case2.TestCase2 object at 0x000001FA0E75C048>\n\n    @pytest.mark.xfail(condition=lambda: True, reason='this test is expecting failure')\n    def test_xfail_expected_failure(self):\n        \"\"\"this test is an xfail that will be marked as expected failure\"\"\"\n>       assert False\nE       assert False\n\nTestcases\\test_case2.py:8: AssertionError"}, "description": "this test is an xfail that will be marked as expected failure", "start": 1588672623071, "stop": 1588672623071, "uuid": "7363f9ec-6fa3-4639-ad82-ae1f992bb1e0", "historyId": "d64559160056d059f07d9cce74305ce8", "testCaseId": "d3eb4a8517d75d9475931ece120b03d3", "fullName": "Testcases.test_case2.TestCase2#test_xfail_expected_failure", "labels": [{"name": "parentSuite", "value": "Testcases"}, {"name": "suite", "value": "test_case2"}, {"name": "subSuite", "value": "TestCase2"}, {"name": "host", "value": "DESKTOP-BKBELAS"}, {"name": "thread", "value": "5348-MainThread"}, {"name": "framework", "value": "pytest"}, {"name": "language", "value": "cpython3"}, {"name": "package", "value": "Testcases.test_case2"}]}